{
 "PRed": [
  {
   "PR": {
    "number": 1,
    "state": "closed"
   },
   "data": {
    "bot_rerun": false,
    "migrator_name": "CompilerRebuild",
    "migrator_version": 1,
    "name": "Python 3.7, GCC 7, R 3.5.1, openBLAS 0.3.2"
   },
   "keys": [
    "bot_rerun",
    "migrator_name",
    "migrator_version",
    "name"
   ]
  },
  {
   "PR": {
    "__lazy_json__": "pr_json/336161169.json"
   },
   "data": {
    "bot_rerun": false,
    "migrator_name": "MigrationYaml",
    "migrator_object_version": 1,
    "migrator_version": 0,
    "name": "python38"
   },
   "keys": [
    "bot_rerun",
    "migrator_name",
    "migrator_object_version",
    "migrator_version",
    "name"
   ]
  },
  {
   "PR": {
    "number": 4,
    "state": "closed"
   },
   "data": {
    "bot_rerun": 1600812301.8135285,
    "migrator_name": "MigrationYaml",
    "migrator_object_version": 1,
    "migrator_version": 0,
    "name": "pypy"
   },
   "keys": [
    "bot_rerun",
    "migrator_name",
    "migrator_object_version",
    "migrator_version",
    "name"
   ]
  },
  {
   "PR": {
    "__lazy_json__": "pr_json/492047520.json"
   },
   "data": {
    "bot_rerun": false,
    "migrator_name": "MigrationYaml",
    "migrator_object_version": 1,
    "migrator_version": 0,
    "name": "pypy"
   },
   "keys": [
    "bot_rerun",
    "migrator_name",
    "migrator_object_version",
    "migrator_version",
    "name"
   ]
  },
  {
   "PR": {
    "__lazy_json__": "pr_json/502064618.json"
   },
   "data": {
    "bot_rerun": false,
    "migrator_name": "MigrationYaml",
    "migrator_object_version": 2,
    "migrator_version": 0,
    "name": "python39"
   },
   "keys": [
    "bot_rerun",
    "migrator_name",
    "migrator_object_version",
    "migrator_version",
    "name"
   ]
  },
  {
   "PR": {
    "__lazy_json__": "pr_json/585832003.json"
   },
   "data": {
    "bot_rerun": false,
    "migrator_name": "MigrationYaml",
    "migrator_object_version": 1,
    "migrator_version": 0,
    "name": "pypy37"
   },
   "keys": [
    "bot_rerun",
    "migrator_name",
    "migrator_object_version",
    "migrator_version",
    "name"
   ]
  },
  {
   "PR": {
    "__lazy_json__": "pr_json/831787170.json"
   },
   "data": {
    "bot_rerun": false,
    "migrator_name": "MigrationYaml",
    "migrator_object_version": 1,
    "migrator_version": 0,
    "name": "python310"
   },
   "keys": [
    "bot_rerun",
    "migrator_name",
    "migrator_object_version",
    "migrator_version",
    "name"
   ]
  }
 ],
 "bad": false,
 "pinning_version": "2022.01.25.13.00.06",
 "pre_pr_migrator_attempts": {
  "pypy37": 1,
  "pypy38": 708,
  "python311": 867,
  "python312": 399
 },
 "pre_pr_migrator_status": {
  "pypy37": "not solvable (<a href=\"https://github.com/regro/autotick-bot/actions/runs/624978124\">bot CI job</a>): master: ['linux_64_python3.7.____73_pypy: Encountered problems while solving.\\nProblem: package h2-2.6.2-py27_0 has constraint python_abi * *_cp27mu conflicting with python_abi-3.7-1_pypy37_pp73\\n', 'linux_64_python3.8.____cpython: Encountered problems while solving.\\nProblem: package h2-2.6.2-py27_0 requires hyperframe >=5.1.0,<6, but none of the providers can be installed\\n', 'osx_64_python3.7.____73_pypy: Encountered problems while solving.\\nProblem: package h2-2.6.2-py27_0 has constraint python_abi * *_cp27m conflicting with python_abi-3.7-1_pypy37_pp73\\n', 'osx_64_python3.8.____cpython: Encountered problems while solving.\\nProblem: package h2-2.6.2-py27_0 requires hyperframe >=5.1.0,<6, but none of the providers can be installed\\n', 'win_64_python3.8.____cpython: Encountered problems while solving.\\nProblem: package h2-2.6.2-py27_0 requires hyperframe >=5.1.0,<6, but none of the providers can be installed\\n']",
  "pypy38": "bot error (<a href=\"https://github.com/regro/cf-scripts/actions/runs/8766219692\">bot CI job</a>): main: Traceback (most recent call last):\n  File \"/home/runner/work/cf-scripts/cf-scripts/cf-scripts/conda_forge_tick/auto_tick.py\", line 1260, in _run_migrator\n    migrator_uid, pr_json = run(\n                            ^^^^\n  File \"/home/runner/work/cf-scripts/cf-scripts/cf-scripts/conda_forge_tick/auto_tick.py\", line 280, in run\n    rerender_msg = rerender_feedstock(feedstock_dir, timeout=900)\n                   ^^^^^^^^^^^^^^^^^^^^^^^^^^^^^^^^^^^^^^^^^^^^^^\n  File \"/home/runner/work/cf-scripts/cf-scripts/cf-scripts/conda_forge_tick/rerender_feedstock.py\", line 41, in rerender_feedstock\n    return rerender_feedstock_containerized(\n           ^^^^^^^^^^^^^^^^^^^^^^^^^^^^^^^^^\n  File \"/home/runner/work/cf-scripts/cf-scripts/cf-scripts/conda_forge_tick/rerender_feedstock.py\", line 83, in rerender_feedstock_containerized\n    data = run_container_task(\n           ^^^^^^^^^^^^^^^^^^^\n  File \"/home/runner/work/cf-scripts/cf-scripts/cf-scripts/conda_forge_tick/utils.py\", line 235, in run_container_task\n    raise RuntimeError(\nRuntimeError: Error running rerender-feedstock in container - error CalledProcessError(1, ['git', 'commit', '-am', 'initial commit']) raised:\ncmd: ['docker',\n 'run',\n '-e',\n 'CF_TICK_IN_CONTAINER=true',\n '--security-opt=no-new-privileges',\n '--read-only',\n '--cap-drop=all',\n '--mount',\n 'type=tmpfs,destination=/tmp,tmpfs-mode=1777,tmpfs-size=10000000',\n '-m',\n '2048m',\n '--cpus',\n '1',\n '--ulimit',\n 'nofile=1024:1024',\n '--ulimit',\n 'nproc=2048:2048',\n '--rm',\n '-i',\n '--mount',\n 'type=bind,source=/tmp/tmpam0lji2c,destination=/cf_tick_dir',\n 'ghcr.io/regro/conda-forge-tick:master',\n '/opt/conda/envs/cf-scripts/bin/python',\n '-u',\n '/opt/autotick-bot/docker/run_bot_task.py',\n 'rerender-feedstock',\n '--timeout',\n '900',\n '--log-level',\n 'info']\nstdout: {'container_stdout': '',\n 'data': None,\n 'error': \"CalledProcessError(1, ['git', 'commit', '-am', 'initial commit'])\",\n 'timeout': 900,\n 'traceback': 'Traceback (most recent call last):\\n'\n              '  File \"/opt/autotick-bot/docker/run_bot_task.py\", line 113, in '\n              '_run_bot_task\\n'\n              '    data = func(**kwargs)\\n'\n              '           ^^^^^^^^^^^^^^\\n'\n              '  File \"/opt/autotick-bot/docker/run_bot_task.py\", line 149, in '\n              '_rerender_feedstock\\n'\n              '    subprocess.run(\\n'\n              '  File '\n              '\"/opt/conda/envs/cf-scripts/lib/python3.11/subprocess.py\", line '\n              '571, in run\\n'\n              '    raise CalledProcessError(retcode, process.args,\\n'\n              \"subprocess.CalledProcessError: Command '['git', 'commit', \"\n              \"'-am', 'initial commit']' returned non-zero exit status 1.\\n\"}\n",
  "python311": "not solvable (<a href=\"https://github.com/regro/cf-scripts/actions/runs/6283390796\">bot CI job</a>): main: ['linux_64_python3.10.____cpython: Encountered problems while solving:\\n  - package h2-2.6.2-py27_1 requires python 2.7*, but none of the providers can be installed\\n', 'linux_64_python3.11.____cpython: Encountered problems while solving:\\n  - package h2-2.6.2-py27_1 requires python 2.7*, but none of the providers can be installed\\n', 'linux_64_python3.8.____cpython: Encountered problems while solving:\\n  - package h2-2.6.2-py27_1 requires python 2.7*, but none of the providers can be installed\\n', 'linux_64_python3.9.____cpython: Encountered problems while solving:\\n  - package h2-2.6.2-py27_1 requires python 2.7*, but none of the providers can be installed\\n', 'osx_64_python3.10.____cpython: Encountered problems while solving:\\n  - package h2-2.6.2-py27_1 requires python 2.7*, but none of the providers can be installed\\n', 'osx_64_python3.11.____cpython: Encountered problems while solving:\\n  - package h2-2.6.2-py27_1 requires python 2.7*, but none of the providers can be installed\\n', 'osx_64_python3.8.____cpython: Encountered problems while solving:\\n  - package h2-2.6.2-py27_1 requires python 2.7*, but none of the providers can be installed\\n', 'osx_64_python3.9.____cpython: Encountered problems while solving:\\n  - package h2-2.6.2-py27_1 requires python 2.7*, but none of the providers can be installed\\n', 'win_64_python3.10.____cpython: Encountered problems while solving:\\n  - nothing provides vc 9.* needed by python-2.7.12-0\\n', 'win_64_python3.11.____cpython: Encountered problems while solving:\\n  - nothing provides vc 9.* needed by python-2.7.12-0\\n', 'win_64_python3.8.____cpython: Encountered problems while solving:\\n  - nothing provides vc 9.* needed by python-2.7.12-0\\n', 'win_64_python3.9.____cpython: Encountered problems while solving:\\n  - nothing provides vc 9.* needed by python-2.7.12-0\\n']",
  "python312": "bot error (<a href=\"https://github.com/regro/cf-scripts/actions/runs/8769900815\">bot CI job</a>): main: Traceback (most recent call last):\n  File \"/home/runner/micromamba/envs/cf-scripts/lib/python3.11/shutil.py\", line 701, in _rmtree_safe_fd\n    os.unlink(entry.name, dir_fd=topfd)\nPermissionError: [Errno 13] Permission denied: 'run_win_build.bat'\n\nDuring handling of the above exception, another exception occurred:\n\nTraceback (most recent call last):\n  File \"/home/runner/work/cf-scripts/cf-scripts/cf-scripts/conda_forge_tick/auto_tick.py\", line 1262, in _run_migrator\n    migrator_uid, pr_json = run(\n                            ^^^^\n  File \"/home/runner/work/cf-scripts/cf-scripts/cf-scripts/conda_forge_tick/auto_tick.py\", line 282, in run\n    rerender_msg = rerender_feedstock(feedstock_dir, timeout=900)\n                   ^^^^^^^^^^^^^^^^^^^^^^^^^^^^^^^^^^^^^^^^^^^^^^\n  File \"/home/runner/work/cf-scripts/cf-scripts/cf-scripts/conda_forge_tick/rerender_feedstock.py\", line 41, in rerender_feedstock\n    return rerender_feedstock_containerized(\n           ^^^^^^^^^^^^^^^^^^^^^^^^^^^^^^^^^\n  File \"/home/runner/work/cf-scripts/cf-scripts/cf-scripts/conda_forge_tick/rerender_feedstock.py\", line 74, in rerender_feedstock_containerized\n    with tempfile.TemporaryDirectory() as tmpdir:\n  File \"/home/runner/micromamba/envs/cf-scripts/lib/python3.11/tempfile.py\", line 943, in __exit__\n    self.cleanup()\n  File \"/home/runner/micromamba/envs/cf-scripts/lib/python3.11/tempfile.py\", line 947, in cleanup\n    self._rmtree(self.name, ignore_errors=self._ignore_cleanup_errors)\n  File \"/home/runner/micromamba/envs/cf-scripts/lib/python3.11/tempfile.py\", line 929, in _rmtree\n    _shutil.rmtree(name, onerror=onerror)\n  File \"/home/runner/micromamba/envs/cf-scripts/lib/python3.11/shutil.py\", line 752, in rmtree\n    _rmtree_safe_fd(fd, path, onerror)\n  File \"/home/runner/micromamba/envs/cf-scripts/lib/python3.11/shutil.py\", line 672, in _rmtree_safe_fd\n    _rmtree_safe_fd(dirfd, fullname, onerror)\n  File \"/home/runner/micromamba/envs/cf-scripts/lib/python3.11/shutil.py\", line 672, in _rmtree_safe_fd\n    _rmtree_safe_fd(dirfd, fullname, onerror)\n  File \"/home/runner/micromamba/envs/cf-scripts/lib/python3.11/shutil.py\", line 703, in _rmtree_safe_fd\n    onerror(os.unlink, fullname, sys.exc_info())\n  File \"/home/runner/micromamba/envs/cf-scripts/lib/python3.11/tempfile.py\", line 889, in onerror\n    _resetperms(_os.path.dirname(path))\n  File \"/home/runner/micromamba/envs/cf-scripts/lib/python3.11/tempfile.py\", line 287, in _resetperms\n    _dont_follow_symlinks(_os.chmod, path, 0o700)\n  File \"/home/runner/micromamba/envs/cf-scripts/lib/python3.11/tempfile.py\", line 278, in _dont_follow_symlinks\n    func(path, *args)\nPermissionError: [Errno 1] Operation not permitted: '/tmp/tmppccd9k51/hyper-feedstock/.scripts'\n"
 },
 "smithy_version": "3.16.1"
}