{
 "PRed": [
  {
   "PR": {
    "number": 4,
    "state": "closed"
   },
   "data": {
    "bot_rerun": false,
    "migrator_name": "CompilerRebuild",
    "migrator_version": 1,
    "name": "Python 3.7, GCC 7, R 3.5.1, openBLAS 0.3.2"
   },
   "keys": [
    "bot_rerun",
    "migrator_name",
    "migrator_version",
    "name"
   ]
  },
  {
   "PR": {
    "number": 11,
    "state": "closed"
   },
   "data": {
    "bot_rerun": false,
    "migrator_name": "BlasRebuild",
    "migrator_version": 0,
    "name": "blas2"
   },
   "keys": [
    "bot_rerun",
    "migrator_name",
    "migrator_version",
    "name"
   ]
  },
  {
   "PR": {
    "number": 12,
    "state": "closed"
   },
   "data": {
    "bot_rerun": false,
    "migrator_name": "MigrationYaml",
    "migrator_object_version": 1,
    "migrator_version": 0,
    "name": "python38"
   },
   "keys": [
    "bot_rerun",
    "migrator_name",
    "migrator_object_version",
    "migrator_version",
    "name"
   ]
  },
  {
   "PR": {
    "number": 13,
    "state": "closed"
   },
   "data": {
    "bot_rerun": false,
    "migrator_name": "MigrationYaml",
    "migrator_object_version": 1,
    "migrator_version": 0,
    "name": "pypy"
   },
   "keys": [
    "bot_rerun",
    "migrator_name",
    "migrator_object_version",
    "migrator_version",
    "name"
   ]
  },
  {
   "PR": {
    "number": 15,
    "state": "closed"
   },
   "data": {
    "bot_rerun": false,
    "migrator_name": "MigrationYaml",
    "migrator_object_version": 2,
    "migrator_version": 0,
    "name": "python39"
   },
   "keys": [
    "bot_rerun",
    "migrator_name",
    "migrator_object_version",
    "migrator_version",
    "name"
   ]
  }
 ],
 "bad": {
  "exception": "[Errno 1] Operation not permitted: '/tmp/tmpz8ok0zt3/pysparse-feedstock/.scripts'",
  "traceback": [
   "Traceback (most recent call last):",
   "  File \"/home/runner/micromamba/envs/cf-scripts/lib/python3.11/shutil.py\", line 701, in _rmtree_safe_fd",
   "    os.unlink(entry.name, dir_fd=topfd)",
   "PermissionError: [Errno 13] Permission denied: 'logging_utils.sh'",
   "",
   "During handling of the above exception, another exception occurred:",
   "",
   "Traceback (most recent call last):",
   "  File \"/home/runner/work/cf-scripts/cf-scripts/cf-scripts/conda_forge_tick/auto_tick.py\", line 1262, in _run_migrator",
   "    migrator_uid, pr_json = run(",
   "                            ^^^^",
   "  File \"/home/runner/work/cf-scripts/cf-scripts/cf-scripts/conda_forge_tick/auto_tick.py\", line 282, in run",
   "    rerender_msg = rerender_feedstock(feedstock_dir, timeout=900)",
   "                   ^^^^^^^^^^^^^^^^^^^^^^^^^^^^^^^^^^^^^^^^^^^^^^",
   "  File \"/home/runner/work/cf-scripts/cf-scripts/cf-scripts/conda_forge_tick/rerender_feedstock.py\", line 41, in rerender_feedstock",
   "    return rerender_feedstock_containerized(",
   "           ^^^^^^^^^^^^^^^^^^^^^^^^^^^^^^^^^",
   "  File \"/home/runner/work/cf-scripts/cf-scripts/cf-scripts/conda_forge_tick/rerender_feedstock.py\", line 74, in rerender_feedstock_containerized",
   "    with tempfile.TemporaryDirectory() as tmpdir:",
   "  File \"/home/runner/micromamba/envs/cf-scripts/lib/python3.11/tempfile.py\", line 943, in __exit__",
   "    self.cleanup()",
   "  File \"/home/runner/micromamba/envs/cf-scripts/lib/python3.11/tempfile.py\", line 947, in cleanup",
   "    self._rmtree(self.name, ignore_errors=self._ignore_cleanup_errors)",
   "  File \"/home/runner/micromamba/envs/cf-scripts/lib/python3.11/tempfile.py\", line 929, in _rmtree",
   "    _shutil.rmtree(name, onerror=onerror)",
   "  File \"/home/runner/micromamba/envs/cf-scripts/lib/python3.11/shutil.py\", line 752, in rmtree",
   "    _rmtree_safe_fd(fd, path, onerror)",
   "  File \"/home/runner/micromamba/envs/cf-scripts/lib/python3.11/shutil.py\", line 672, in _rmtree_safe_fd",
   "    _rmtree_safe_fd(dirfd, fullname, onerror)",
   "  File \"/home/runner/micromamba/envs/cf-scripts/lib/python3.11/shutil.py\", line 672, in _rmtree_safe_fd",
   "    _rmtree_safe_fd(dirfd, fullname, onerror)",
   "  File \"/home/runner/micromamba/envs/cf-scripts/lib/python3.11/shutil.py\", line 703, in _rmtree_safe_fd",
   "    onerror(os.unlink, fullname, sys.exc_info())",
   "  File \"/home/runner/micromamba/envs/cf-scripts/lib/python3.11/tempfile.py\", line 889, in onerror",
   "    _resetperms(_os.path.dirname(path))",
   "  File \"/home/runner/micromamba/envs/cf-scripts/lib/python3.11/tempfile.py\", line 287, in _resetperms",
   "    _dont_follow_symlinks(_os.chmod, path, 0o700)",
   "  File \"/home/runner/micromamba/envs/cf-scripts/lib/python3.11/tempfile.py\", line 278, in _dont_follow_symlinks",
   "    func(path, *args)",
   "PermissionError: [Errno 1] Operation not permitted: '/tmp/tmpz8ok0zt3/pysparse-feedstock/.scripts'",
   ""
  ]
 },
 "pinning_version": "2020.11.10.21.31.03",
 "pre_pr_migrator_attempts": {
  "pypy37": 1,
  "pypy37-windows": 1,
  "pypy38": 680,
  "python310": 1500,
  "python311": 816,
  "python312": 410,
  "python39": 1
 },
 "pre_pr_migrator_status": {
  "pypy37": "not solvable (<a href=\"https://github.com/regro/autotick-bot/actions/runs/1418044928\">bot CI job</a>): master: ['No `.ci_support/*.yaml` files found! This can happen when a rerender results in no builds for a recipe (e.g., a recipe is python 2.7 only). This attempted migration is being reported as not solvable.']",
  "pypy37-windows": "not solvable (<a href=\"https://github.com/regro/autotick-bot/actions/runs/1418593600\">bot CI job</a>): master: ['No `.ci_support/*.yaml` files found! This can happen when a rerender results in no builds for a recipe (e.g., a recipe is python 2.7 only). This attempted migration is being reported as not solvable.']",
  "pypy38": "not solvable (<a href='https://github.com/regro/cf-scripts/actions/runs/8764036341'>bot CI job</a>) @ main\n<details>\n<div align=\"left\">\n<pre>\nNo `.ci_support/*.yaml` files found! This can happen when a rerender results in no builds for a recipe (e.g., a recipe is python 2.7 only). This attempted migration is being reported as not solvable.\n</pre>\n</div>\n</details>",
  "python310": "not solvable (<a href=\"https://github.com/regro/autotick-bot/actions/runs/2919868583\">bot CI job</a>): main: ['No `.ci_support/*.yaml` files found! This can happen when a rerender results in no builds for a recipe (e.g., a recipe is python 2.7 only). This attempted migration is being reported as not solvable.']",
  "python311": "not solvable (<a href=\"https://github.com/regro/cf-scripts/actions/runs/6276844269\">bot CI job</a>): main: ['No `.ci_support/*.yaml` files found! This can happen when a rerender results in no builds for a recipe (e.g., a recipe is python 2.7 only). This attempted migration is being reported as not solvable.']",
  "python312": "bot error (<a href=\"https://github.com/regro/cf-scripts/actions/runs/8769200238\">bot CI job</a>): main: Traceback (most recent call last):\n  File \"/home/runner/micromamba/envs/cf-scripts/lib/python3.11/shutil.py\", line 701, in _rmtree_safe_fd\n    os.unlink(entry.name, dir_fd=topfd)\nPermissionError: [Errno 13] Permission denied: 'logging_utils.sh'\n\nDuring handling of the above exception, another exception occurred:\n\nTraceback (most recent call last):\n  File \"/home/runner/work/cf-scripts/cf-scripts/cf-scripts/conda_forge_tick/auto_tick.py\", line 1262, in _run_migrator\n    migrator_uid, pr_json = run(\n                            ^^^^\n  File \"/home/runner/work/cf-scripts/cf-scripts/cf-scripts/conda_forge_tick/auto_tick.py\", line 282, in run\n    rerender_msg = rerender_feedstock(feedstock_dir, timeout=900)\n                   ^^^^^^^^^^^^^^^^^^^^^^^^^^^^^^^^^^^^^^^^^^^^^^\n  File \"/home/runner/work/cf-scripts/cf-scripts/cf-scripts/conda_forge_tick/rerender_feedstock.py\", line 41, in rerender_feedstock\n    return rerender_feedstock_containerized(\n           ^^^^^^^^^^^^^^^^^^^^^^^^^^^^^^^^^\n  File \"/home/runner/work/cf-scripts/cf-scripts/cf-scripts/conda_forge_tick/rerender_feedstock.py\", line 74, in rerender_feedstock_containerized\n    with tempfile.TemporaryDirectory() as tmpdir:\n  File \"/home/runner/micromamba/envs/cf-scripts/lib/python3.11/tempfile.py\", line 943, in __exit__\n    self.cleanup()\n  File \"/home/runner/micromamba/envs/cf-scripts/lib/python3.11/tempfile.py\", line 947, in cleanup\n    self._rmtree(self.name, ignore_errors=self._ignore_cleanup_errors)\n  File \"/home/runner/micromamba/envs/cf-scripts/lib/python3.11/tempfile.py\", line 929, in _rmtree\n    _shutil.rmtree(name, onerror=onerror)\n  File \"/home/runner/micromamba/envs/cf-scripts/lib/python3.11/shutil.py\", line 752, in rmtree\n    _rmtree_safe_fd(fd, path, onerror)\n  File \"/home/runner/micromamba/envs/cf-scripts/lib/python3.11/shutil.py\", line 672, in _rmtree_safe_fd\n    _rmtree_safe_fd(dirfd, fullname, onerror)\n  File \"/home/runner/micromamba/envs/cf-scripts/lib/python3.11/shutil.py\", line 672, in _rmtree_safe_fd\n    _rmtree_safe_fd(dirfd, fullname, onerror)\n  File \"/home/runner/micromamba/envs/cf-scripts/lib/python3.11/shutil.py\", line 703, in _rmtree_safe_fd\n    onerror(os.unlink, fullname, sys.exc_info())\n  File \"/home/runner/micromamba/envs/cf-scripts/lib/python3.11/tempfile.py\", line 889, in onerror\n    _resetperms(_os.path.dirname(path))\n  File \"/home/runner/micromamba/envs/cf-scripts/lib/python3.11/tempfile.py\", line 287, in _resetperms\n    _dont_follow_symlinks(_os.chmod, path, 0o700)\n  File \"/home/runner/micromamba/envs/cf-scripts/lib/python3.11/tempfile.py\", line 278, in _dont_follow_symlinks\n    func(path, *args)\nPermissionError: [Errno 1] Operation not permitted: '/tmp/tmpz8ok0zt3/pysparse-feedstock/.scripts'\n",
  "python39": "not solvable: master: ['No `.ci_support/*.yaml` files found! This can happen when a rerender results in no builds for a recipe (e.g., a recipe is python 2.7 only). This attempted migration is being reported as not solvable.']"
 },
 "smithy_version": "3.8.5"
}