{
 "PRed": [
  {
   "PR": {
    "number": 4,
    "state": "closed"
   },
   "data": {
    "bot_rerun": 1610235225.8352754,
    "migrator_name": "MigrationYaml",
    "migrator_object_version": 2,
    "migrator_version": 0,
    "name": "python39"
   },
   "keys": [
    "bot_rerun",
    "migrator_name",
    "migrator_object_version",
    "migrator_version",
    "name"
   ]
  },
  {
   "PR": {
    "__lazy_json__": "pr_json/552204094.json"
   },
   "data": {
    "bot_rerun": false,
    "migrator_name": "MigrationYaml",
    "migrator_object_version": 2,
    "migrator_version": 0,
    "name": "python39"
   },
   "keys": [
    "bot_rerun",
    "migrator_name",
    "migrator_object_version",
    "migrator_version",
    "name"
   ]
  },
  {
   "PR": {
    "number": 6,
    "state": "closed"
   },
   "data": {
    "bot_rerun": false,
    "migrator_name": "MigrationYaml",
    "migrator_object_version": 1,
    "migrator_version": 0,
    "name": "pypy"
   },
   "keys": [
    "bot_rerun",
    "migrator_name",
    "migrator_object_version",
    "migrator_version",
    "name"
   ]
  },
  {
   "PR": {
    "__lazy_json__": "pr_json/697948837.json"
   },
   "data": {
    "bot_rerun": false,
    "migrator_name": "MigrationYaml",
    "migrator_object_version": 1,
    "migrator_version": 0,
    "name": "pypy37"
   },
   "keys": [
    "bot_rerun",
    "migrator_name",
    "migrator_object_version",
    "migrator_version",
    "name"
   ]
  },
  {
   "PR": {
    "__lazy_json__": "pr_json/1317456947.json"
   },
   "data": {
    "bot_rerun": false,
    "migrator_name": "MigrationYaml",
    "migrator_object_version": 1,
    "migrator_version": 0,
    "name": "python311"
   },
   "keys": [
    "bot_rerun",
    "migrator_name",
    "migrator_object_version",
    "migrator_version",
    "name"
   ]
  }
 ],
 "bad": {
  "exception": "Error running rerender-feedstock in container - error RuntimeError('Failed to rerender.\\noutput: Traceback (most recent call last):\\n  File \"/opt/conda/envs/cf-scripts/bin/conda-smithy\", line 10, in <module>\\n    sys.exit(main())\\n    args.subcommand_func(args)\\n  File \"/opt/conda/envs/cf-scripts/lib/python3.11/site-packages/conda_smithy/cli.py\", line 589, in _call\\n    exclusive_config_file, cf_pinning_ver = get_cached_cfp_file_path(\\n    current_pinning_version = get_most_recent_version(\\n    request.raise_for_status()\\n  File \"/opt/conda/envs/cf-scripts/lib/python3.11/site-packages/requests/models.py\", line 1021, in raise_for_status\\n             ^^^^^^\\n  File \"/opt/conda/envs/cf-scripts/lib/python3.11/site-packages/conda_smithy/cli.py\", line 737, in main\\n  File \"/opt/conda/envs/cf-scripts/lib/python3.11/site-packages/conda_smithy/cli.py\", line 586, in __call__\\n    self._call(args, args.temporary_directory)\\n    configure_feedstock.main(\\n  File \"/opt/conda/envs/cf-scripts/lib/python3.11/site-packages/conda_smithy/configure_feedstock.py\", line 2616, in main\\n                                            ^^^^^^^^^^^^^^^^^^^^^^^^^\\n  File \"/opt/conda/envs/cf-scripts/lib/python3.11/site-packages/conda_smithy/configure_feedstock.py\", line 2430, in get_cached_cfp_file_path\\n                              ^^^^^^^^^^^^^^^^^^^^^^^^\\n  File \"/opt/conda/envs/cf-scripts/lib/python3.11/site-packages/conda_smithy/configure_feedstock.py\", line 2300, in get_most_recent_version\\n    raise HTTPError(http_error_msg, response=self)\\nrequests.exceptions.HTTPError: 503 Server Error: Service Unavailable for url: https://api.anaconda.org/package/conda-forge/conda-forge-pinning\\n\\n') raised:\ncmd: ['docker',\n 'run',\n '-e',\n 'CF_TICK_IN_CONTAINER=true',\n '--security-opt=no-new-privileges',\n '--read-only',\n '--cap-drop=all',\n '--mount',\n 'type=tmpfs,destination=/tmp,tmpfs-mode=1777,tmpfs-size=100000000',\n '-m',\n '2048m',\n '--cpus',\n '1',\n '--ulimit',\n 'nofile=1024:1024',\n '--ulimit',\n 'nproc=2048:2048',\n '--rm',\n '-i',\n '--mount',\n 'type=bind,source=/tmp/tmpamz5o37c,destination=/cf_tick_dir',\n 'ghcr.io/regro/conda-forge-tick:master',\n '/opt/conda/envs/cf-scripts/bin/python',\n '-u',\n '/opt/autotick-bot/docker/run_bot_task.py',\n 'rerender-feedstock',\n '--timeout',\n '900',\n '--log-level',\n 'info']\nstdout: {'container_stdout': '',\n 'data': None,\n 'error': \"RuntimeError('Failed to rerender.\\\\noutput: Traceback (most recent \"\n          'call last):\\\\n  File \"/opt/conda/envs/cf-scripts/bin/conda-smithy\", '\n          'line 10, in <module>\\\\n    sys.exit(main())\\\\n    '\n          'args.subcommand_func(args)\\\\n  File '\n          '\"/opt/conda/envs/cf-scripts/lib/python3.11/site-packages/conda_smithy/cli.py\", '\n          'line 589, in _call\\\\n    exclusive_config_file, cf_pinning_ver = '\n          'get_cached_cfp_file_path(\\\\n    current_pinning_version = '\n          'get_most_recent_version(\\\\n    request.raise_for_status()\\\\n  File '\n          '\"/opt/conda/envs/cf-scripts/lib/python3.11/site-packages/requests/models.py\", '\n          'line 1021, in raise_for_status\\\\n             ^^^^^^\\\\n  File '\n          '\"/opt/conda/envs/cf-scripts/lib/python3.11/site-packages/conda_smithy/cli.py\", '\n          'line 737, in main\\\\n  File '\n          '\"/opt/conda/envs/cf-scripts/lib/python3.11/site-packages/conda_smithy/cli.py\", '\n          'line 586, in __call__\\\\n    self._call(args, '\n          'args.temporary_directory)\\\\n    configure_feedstock.main(\\\\n  File '\n          '\"/opt/conda/envs/cf-scripts/lib/python3.11/site-packages/conda_smithy/configure_feedstock.py\", '\n          'line 2616, in main\\\\n                                            '\n          '^^^^^^^^^^^^^^^^^^^^^^^^^\\\\n  File '\n          '\"/opt/conda/envs/cf-scripts/lib/python3.11/site-packages/conda_smithy/configure_feedstock.py\", '\n          'line 2430, in '\n          'get_cached_cfp_file_path\\\\n                              '\n          '^^^^^^^^^^^^^^^^^^^^^^^^\\\\n  File '\n          '\"/opt/conda/envs/cf-scripts/lib/python3.11/site-packages/conda_smithy/configure_feedstock.py\", '\n          'line 2300, in get_most_recent_version\\\\n    raise '\n          'HTTPError(http_error_msg, '\n          'response=self)\\\\nrequests.exceptions.HTTPError: 503 Server Error: '\n          'Service Unavailable for url: '\n          \"https://api.anaconda.org/package/conda-forge/conda-forge-pinning\\\\n\\\\n')\",\n 'timeout': 900,\n 'traceback': 'Traceback (most recent call last):\\n'\n              '  File \"/opt/autotick-bot/docker/run_bot_task.py\", line 114, in '\n              '_run_bot_task\\n'\n              '    data = func(**kwargs)\\n'\n              '           ^^^^^^^^^^^^^^\\n'\n              '  File \"/opt/autotick-bot/docker/run_bot_task.py\", line 209, in '\n              '_rerender_feedstock\\n'\n              '    msg = rerender_feedstock_local(fs_dir, **kwargs)\\n'\n              '          ^^^^^^^^^^^^^^^^^^^^^^^^^^^^^^^^^^^^^^^^^^\\n'\n              '  File '\n              '\"/opt/autotick-bot/conda_forge_tick/rerender_feedstock.py\", '\n              'line 208, in rerender_feedstock_local\\n'\n              '    raise RuntimeError(f\"Failed to rerender.\\\\noutput: '\n              '{ret.stdout}\\\\n\")\\n'\n              'RuntimeError: Failed to rerender.\\n'\n              'output: Traceback (most recent call last):\\n'\n              '  File \"/opt/conda/envs/cf-scripts/bin/conda-smithy\", line 10, '\n              'in <module>\\n'\n              '    sys.exit(main())\\n'\n              '    args.subcommand_func(args)\\n'\n              '  File '\n              '\"/opt/conda/envs/cf-scripts/lib/python3.11/site-packages/conda_smithy/cli.py\", '\n              'line 589, in _call\\n'\n              '    exclusive_config_file, cf_pinning_ver = '\n              'get_cached_cfp_file_path(\\n'\n              '    current_pinning_version = get_most_recent_version(\\n'\n              '    request.raise_for_status()\\n'\n              '  File '\n              '\"/opt/conda/envs/cf-scripts/lib/python3.11/site-packages/requests/models.py\", '\n              'line 1021, in raise_for_status\\n'\n              '             ^^^^^^\\n'\n              '  File '\n              '\"/opt/conda/envs/cf-scripts/lib/python3.11/site-packages/conda_smithy/cli.py\", '\n              'line 737, in main\\n'\n              '  File '\n              '\"/opt/conda/envs/cf-scripts/lib/python3.11/site-packages/conda_smithy/cli.py\", '\n              'line 586, in __call__\\n'\n              '    self._call(args, args.temporary_directory)\\n'\n              '    configure_feedstock.main(\\n'\n              '  File '\n              '\"/opt/conda/envs/cf-scripts/lib/python3.11/site-packages/conda_smithy/configure_feedstock.py\", '\n              'line 2616, in main\\n'\n              '                                            '\n              '^^^^^^^^^^^^^^^^^^^^^^^^^\\n'\n              '  File '\n              '\"/opt/conda/envs/cf-scripts/lib/python3.11/site-packages/conda_smithy/configure_feedstock.py\", '\n              'line 2430, in get_cached_cfp_file_path\\n'\n              '                              ^^^^^^^^^^^^^^^^^^^^^^^^\\n'\n              '  File '\n              '\"/opt/conda/envs/cf-scripts/lib/python3.11/site-packages/conda_smithy/configure_feedstock.py\", '\n              'line 2300, in get_most_recent_version\\n'\n              '    raise HTTPError(http_error_msg, response=self)\\n'\n              'requests.exceptions.HTTPError: 503 Server Error: Service '\n              'Unavailable for url: '\n              'https://api.anaconda.org/package/conda-forge/conda-forge-pinning\\n'\n              '\\n'\n              '\\n'}",
  "traceback": [
   "Traceback (most recent call last):",
   "  File \"/home/runner/work/cf-scripts/cf-scripts/cf-scripts/conda_forge_tick/auto_tick.py\", line 1267, in _run_migrator",
   "    migrator_uid, pr_json = run(",
   "                            ^^^^",
   "  File \"/home/runner/work/cf-scripts/cf-scripts/cf-scripts/conda_forge_tick/auto_tick.py\", line 284, in run",
   "    rerender_msg = rerender_feedstock(feedstock_dir, timeout=900)",
   "                   ^^^^^^^^^^^^^^^^^^^^^^^^^^^^^^^^^^^^^^^^^^^^^^",
   "  File \"/home/runner/work/cf-scripts/cf-scripts/cf-scripts/conda_forge_tick/rerender_feedstock.py\", line 42, in rerender_feedstock",
   "    return rerender_feedstock_containerized(",
   "           ^^^^^^^^^^^^^^^^^^^^^^^^^^^^^^^^^",
   "  File \"/home/runner/work/cf-scripts/cf-scripts/cf-scripts/conda_forge_tick/rerender_feedstock.py\", line 88, in rerender_feedstock_containerized",
   "    data = run_container_task(",
   "           ^^^^^^^^^^^^^^^^^^^",
   "  File \"/home/runner/work/cf-scripts/cf-scripts/cf-scripts/conda_forge_tick/utils.py\", line 237, in run_container_task",
   "    raise RuntimeError(",
   "RuntimeError: Error running rerender-feedstock in container - error RuntimeError('Failed to rerender.\\noutput: Traceback (most recent call last):\\n  File \"/opt/conda/envs/cf-scripts/bin/conda-smithy\", line 10, in <module>\\n    sys.exit(main())\\n    args.subcommand_func(args)\\n  File \"/opt/conda/envs/cf-scripts/lib/python3.11/site-packages/conda_smithy/cli.py\", line 589, in _call\\n    exclusive_config_file, cf_pinning_ver = get_cached_cfp_file_path(\\n    current_pinning_version = get_most_recent_version(\\n    request.raise_for_status()\\n  File \"/opt/conda/envs/cf-scripts/lib/python3.11/site-packages/requests/models.py\", line 1021, in raise_for_status\\n             ^^^^^^\\n  File \"/opt/conda/envs/cf-scripts/lib/python3.11/site-packages/conda_smithy/cli.py\", line 737, in main\\n  File \"/opt/conda/envs/cf-scripts/lib/python3.11/site-packages/conda_smithy/cli.py\", line 586, in __call__\\n    self._call(args, args.temporary_directory)\\n    configure_feedstock.main(\\n  File \"/opt/conda/envs/cf-scripts/lib/python3.11/site-packages/conda_smithy/configure_feedstock.py\", line 2616, in main\\n                                            ^^^^^^^^^^^^^^^^^^^^^^^^^\\n  File \"/opt/conda/envs/cf-scripts/lib/python3.11/site-packages/conda_smithy/configure_feedstock.py\", line 2430, in get_cached_cfp_file_path\\n                              ^^^^^^^^^^^^^^^^^^^^^^^^\\n  File \"/opt/conda/envs/cf-scripts/lib/python3.11/site-packages/conda_smithy/configure_feedstock.py\", line 2300, in get_most_recent_version\\n    raise HTTPError(http_error_msg, response=self)\\nrequests.exceptions.HTTPError: 503 Server Error: Service Unavailable for url: https://api.anaconda.org/package/conda-forge/conda-forge-pinning\\n\\n') raised:",
   "cmd: ['docker',",
   " 'run',",
   " '-e',",
   " 'CF_TICK_IN_CONTAINER=true',",
   " '--security-opt=no-new-privileges',",
   " '--read-only',",
   " '--cap-drop=all',",
   " '--mount',",
   " 'type=tmpfs,destination=/tmp,tmpfs-mode=1777,tmpfs-size=100000000',",
   " '-m',",
   " '2048m',",
   " '--cpus',",
   " '1',",
   " '--ulimit',",
   " 'nofile=1024:1024',",
   " '--ulimit',",
   " 'nproc=2048:2048',",
   " '--rm',",
   " '-i',",
   " '--mount',",
   " 'type=bind,source=/tmp/tmpamz5o37c,destination=/cf_tick_dir',",
   " 'ghcr.io/regro/conda-forge-tick:master',",
   " '/opt/conda/envs/cf-scripts/bin/python',",
   " '-u',",
   " '/opt/autotick-bot/docker/run_bot_task.py',",
   " 'rerender-feedstock',",
   " '--timeout',",
   " '900',",
   " '--log-level',",
   " 'info']",
   "stdout: {'container_stdout': '',",
   " 'data': None,",
   " 'error': \"RuntimeError('Failed to rerender.\\\\noutput: Traceback (most recent \"",
   "          'call last):\\\\n  File \"/opt/conda/envs/cf-scripts/bin/conda-smithy\", '",
   "          'line 10, in <module>\\\\n    sys.exit(main())\\\\n    '",
   "          'args.subcommand_func(args)\\\\n  File '",
   "          '\"/opt/conda/envs/cf-scripts/lib/python3.11/site-packages/conda_smithy/cli.py\", '",
   "          'line 589, in _call\\\\n    exclusive_config_file, cf_pinning_ver = '",
   "          'get_cached_cfp_file_path(\\\\n    current_pinning_version = '",
   "          'get_most_recent_version(\\\\n    request.raise_for_status()\\\\n  File '",
   "          '\"/opt/conda/envs/cf-scripts/lib/python3.11/site-packages/requests/models.py\", '",
   "          'line 1021, in raise_for_status\\\\n             ^^^^^^\\\\n  File '",
   "          '\"/opt/conda/envs/cf-scripts/lib/python3.11/site-packages/conda_smithy/cli.py\", '",
   "          'line 737, in main\\\\n  File '",
   "          '\"/opt/conda/envs/cf-scripts/lib/python3.11/site-packages/conda_smithy/cli.py\", '",
   "          'line 586, in __call__\\\\n    self._call(args, '",
   "          'args.temporary_directory)\\\\n    configure_feedstock.main(\\\\n  File '",
   "          '\"/opt/conda/envs/cf-scripts/lib/python3.11/site-packages/conda_smithy/configure_feedstock.py\", '",
   "          'line 2616, in main\\\\n                                            '",
   "          '^^^^^^^^^^^^^^^^^^^^^^^^^\\\\n  File '",
   "          '\"/opt/conda/envs/cf-scripts/lib/python3.11/site-packages/conda_smithy/configure_feedstock.py\", '",
   "          'line 2430, in '",
   "          'get_cached_cfp_file_path\\\\n                              '",
   "          '^^^^^^^^^^^^^^^^^^^^^^^^\\\\n  File '",
   "          '\"/opt/conda/envs/cf-scripts/lib/python3.11/site-packages/conda_smithy/configure_feedstock.py\", '",
   "          'line 2300, in get_most_recent_version\\\\n    raise '",
   "          'HTTPError(http_error_msg, '",
   "          'response=self)\\\\nrequests.exceptions.HTTPError: 503 Server Error: '",
   "          'Service Unavailable for url: '",
   "          \"https://api.anaconda.org/package/conda-forge/conda-forge-pinning\\\\n\\\\n')\",",
   " 'timeout': 900,",
   " 'traceback': 'Traceback (most recent call last):\\n'",
   "              '  File \"/opt/autotick-bot/docker/run_bot_task.py\", line 114, in '",
   "              '_run_bot_task\\n'",
   "              '    data = func(**kwargs)\\n'",
   "              '           ^^^^^^^^^^^^^^\\n'",
   "              '  File \"/opt/autotick-bot/docker/run_bot_task.py\", line 209, in '",
   "              '_rerender_feedstock\\n'",
   "              '    msg = rerender_feedstock_local(fs_dir, **kwargs)\\n'",
   "              '          ^^^^^^^^^^^^^^^^^^^^^^^^^^^^^^^^^^^^^^^^^^\\n'",
   "              '  File '",
   "              '\"/opt/autotick-bot/conda_forge_tick/rerender_feedstock.py\", '",
   "              'line 208, in rerender_feedstock_local\\n'",
   "              '    raise RuntimeError(f\"Failed to rerender.\\\\noutput: '",
   "              '{ret.stdout}\\\\n\")\\n'",
   "              'RuntimeError: Failed to rerender.\\n'",
   "              'output: Traceback (most recent call last):\\n'",
   "              '  File \"/opt/conda/envs/cf-scripts/bin/conda-smithy\", line 10, '",
   "              'in <module>\\n'",
   "              '    sys.exit(main())\\n'",
   "              '    args.subcommand_func(args)\\n'",
   "              '  File '",
   "              '\"/opt/conda/envs/cf-scripts/lib/python3.11/site-packages/conda_smithy/cli.py\", '",
   "              'line 589, in _call\\n'",
   "              '    exclusive_config_file, cf_pinning_ver = '",
   "              'get_cached_cfp_file_path(\\n'",
   "              '    current_pinning_version = get_most_recent_version(\\n'",
   "              '    request.raise_for_status()\\n'",
   "              '  File '",
   "              '\"/opt/conda/envs/cf-scripts/lib/python3.11/site-packages/requests/models.py\", '",
   "              'line 1021, in raise_for_status\\n'",
   "              '             ^^^^^^\\n'",
   "              '  File '",
   "              '\"/opt/conda/envs/cf-scripts/lib/python3.11/site-packages/conda_smithy/cli.py\", '",
   "              'line 737, in main\\n'",
   "              '  File '",
   "              '\"/opt/conda/envs/cf-scripts/lib/python3.11/site-packages/conda_smithy/cli.py\", '",
   "              'line 586, in __call__\\n'",
   "              '    self._call(args, args.temporary_directory)\\n'",
   "              '    configure_feedstock.main(\\n'",
   "              '  File '",
   "              '\"/opt/conda/envs/cf-scripts/lib/python3.11/site-packages/conda_smithy/configure_feedstock.py\", '",
   "              'line 2616, in main\\n'",
   "              '                                            '",
   "              '^^^^^^^^^^^^^^^^^^^^^^^^^\\n'",
   "              '  File '",
   "              '\"/opt/conda/envs/cf-scripts/lib/python3.11/site-packages/conda_smithy/configure_feedstock.py\", '",
   "              'line 2430, in get_cached_cfp_file_path\\n'",
   "              '                              ^^^^^^^^^^^^^^^^^^^^^^^^\\n'",
   "              '  File '",
   "              '\"/opt/conda/envs/cf-scripts/lib/python3.11/site-packages/conda_smithy/configure_feedstock.py\", '",
   "              'line 2300, in get_most_recent_version\\n'",
   "              '    raise HTTPError(http_error_msg, response=self)\\n'",
   "              'requests.exceptions.HTTPError: 503 Server Error: Service '",
   "              'Unavailable for url: '",
   "              'https://api.anaconda.org/package/conda-forge/conda-forge-pinning\\n'",
   "              '\\n'",
   "              '\\n'}",
   ""
  ]
 },
 "pinning_version": "2023.04.17.19.54.34",
 "pre_pr_migrator_attempts": {
  "pypy38": 393
 },
 "pre_pr_migrator_status": {
  "pypy38": "bot error (<a href=\"https://github.com/regro/cf-scripts/actions/runs/8788065453\">bot CI job</a>): main: Traceback (most recent call last):\n  File \"/home/runner/work/cf-scripts/cf-scripts/cf-scripts/conda_forge_tick/auto_tick.py\", line 1267, in _run_migrator\n    migrator_uid, pr_json = run(\n                            ^^^^\n  File \"/home/runner/work/cf-scripts/cf-scripts/cf-scripts/conda_forge_tick/auto_tick.py\", line 284, in run\n    rerender_msg = rerender_feedstock(feedstock_dir, timeout=900)\n                   ^^^^^^^^^^^^^^^^^^^^^^^^^^^^^^^^^^^^^^^^^^^^^^\n  File \"/home/runner/work/cf-scripts/cf-scripts/cf-scripts/conda_forge_tick/rerender_feedstock.py\", line 42, in rerender_feedstock\n    return rerender_feedstock_containerized(\n           ^^^^^^^^^^^^^^^^^^^^^^^^^^^^^^^^^\n  File \"/home/runner/work/cf-scripts/cf-scripts/cf-scripts/conda_forge_tick/rerender_feedstock.py\", line 88, in rerender_feedstock_containerized\n    data = run_container_task(\n           ^^^^^^^^^^^^^^^^^^^\n  File \"/home/runner/work/cf-scripts/cf-scripts/cf-scripts/conda_forge_tick/utils.py\", line 237, in run_container_task\n    raise RuntimeError(\nRuntimeError: Error running rerender-feedstock in container - error RuntimeError('Failed to rerender.\\noutput: Traceback (most recent call last):\\n  File \"/opt/conda/envs/cf-scripts/bin/conda-smithy\", line 10, in <module>\\n    sys.exit(main())\\n    args.subcommand_func(args)\\n  File \"/opt/conda/envs/cf-scripts/lib/python3.11/site-packages/conda_smithy/cli.py\", line 589, in _call\\n    exclusive_config_file, cf_pinning_ver = get_cached_cfp_file_path(\\n    current_pinning_version = get_most_recent_version(\\n    request.raise_for_status()\\n  File \"/opt/conda/envs/cf-scripts/lib/python3.11/site-packages/requests/models.py\", line 1021, in raise_for_status\\n             ^^^^^^\\n  File \"/opt/conda/envs/cf-scripts/lib/python3.11/site-packages/conda_smithy/cli.py\", line 737, in main\\n  File \"/opt/conda/envs/cf-scripts/lib/python3.11/site-packages/conda_smithy/cli.py\", line 586, in __call__\\n    self._call(args, args.temporary_directory)\\n    configure_feedstock.main(\\n  File \"/opt/conda/envs/cf-scripts/lib/python3.11/site-packages/conda_smithy/configure_feedstock.py\", line 2616, in main\\n                                            ^^^^^^^^^^^^^^^^^^^^^^^^^\\n  File \"/opt/conda/envs/cf-scripts/lib/python3.11/site-packages/conda_smithy/configure_feedstock.py\", line 2430, in get_cached_cfp_file_path\\n                              ^^^^^^^^^^^^^^^^^^^^^^^^\\n  File \"/opt/conda/envs/cf-scripts/lib/python3.11/site-packages/conda_smithy/configure_feedstock.py\", line 2300, in get_most_recent_version\\n    raise HTTPError(http_error_msg, response=self)\\nrequests.exceptions.HTTPError: 503 Server Error: Service Unavailable for url: https://api.anaconda.org/package/conda-forge/conda-forge-pinning\\n\\n') raised:\ncmd: ['docker',\n 'run',\n '-e',\n 'CF_TICK_IN_CONTAINER=true',\n '--security-opt=no-new-privileges',\n '--read-only',\n '--cap-drop=all',\n '--mount',\n 'type=tmpfs,destination=/tmp,tmpfs-mode=1777,tmpfs-size=100000000',\n '-m',\n '2048m',\n '--cpus',\n '1',\n '--ulimit',\n 'nofile=1024:1024',\n '--ulimit',\n 'nproc=2048:2048',\n '--rm',\n '-i',\n '--mount',\n 'type=bind,source=/tmp/tmpamz5o37c,destination=/cf_tick_dir',\n 'ghcr.io/regro/conda-forge-tick:master',\n '/opt/conda/envs/cf-scripts/bin/python',\n '-u',\n '/opt/autotick-bot/docker/run_bot_task.py',\n 'rerender-feedstock',\n '--timeout',\n '900',\n '--log-level',\n 'info']\nstdout: {'container_stdout': '',\n 'data': None,\n 'error': \"RuntimeError('Failed to rerender.\\\\noutput: Traceback (most recent \"\n          'call last):\\\\n  File \"/opt/conda/envs/cf-scripts/bin/conda-smithy\", '\n          'line 10, in <module>\\\\n    sys.exit(main())\\\\n    '\n          'args.subcommand_func(args)\\\\n  File '\n          '\"/opt/conda/envs/cf-scripts/lib/python3.11/site-packages/conda_smithy/cli.py\", '\n          'line 589, in _call\\\\n    exclusive_config_file, cf_pinning_ver = '\n          'get_cached_cfp_file_path(\\\\n    current_pinning_version = '\n          'get_most_recent_version(\\\\n    request.raise_for_status()\\\\n  File '\n          '\"/opt/conda/envs/cf-scripts/lib/python3.11/site-packages/requests/models.py\", '\n          'line 1021, in raise_for_status\\\\n             ^^^^^^\\\\n  File '\n          '\"/opt/conda/envs/cf-scripts/lib/python3.11/site-packages/conda_smithy/cli.py\", '\n          'line 737, in main\\\\n  File '\n          '\"/opt/conda/envs/cf-scripts/lib/python3.11/site-packages/conda_smithy/cli.py\", '\n          'line 586, in __call__\\\\n    self._call(args, '\n          'args.temporary_directory)\\\\n    configure_feedstock.main(\\\\n  File '\n          '\"/opt/conda/envs/cf-scripts/lib/python3.11/site-packages/conda_smithy/configure_feedstock.py\", '\n          'line 2616, in main\\\\n                                            '\n          '^^^^^^^^^^^^^^^^^^^^^^^^^\\\\n  File '\n          '\"/opt/conda/envs/cf-scripts/lib/python3.11/site-packages/conda_smithy/configure_feedstock.py\", '\n          'line 2430, in '\n          'get_cached_cfp_file_path\\\\n                              '\n          '^^^^^^^^^^^^^^^^^^^^^^^^\\\\n  File '\n          '\"/opt/conda/envs/cf-scripts/lib/python3.11/site-packages/conda_smithy/configure_feedstock.py\", '\n          'line 2300, in get_most_recent_version\\\\n    raise '\n          'HTTPError(http_error_msg, '\n          'response=self)\\\\nrequests.exceptions.HTTPError: 503 Server Error: '\n          'Service Unavailable for url: '\n          \"https://api.anaconda.org/package/conda-forge/conda-forge-pinning\\\\n\\\\n')\",\n 'timeout': 900,\n 'traceback': 'Traceback (most recent call last):\\n'\n              '  File \"/opt/autotick-bot/docker/run_bot_task.py\", line 114, in '\n              '_run_bot_task\\n'\n              '    data = func(**kwargs)\\n'\n              '           ^^^^^^^^^^^^^^\\n'\n              '  File \"/opt/autotick-bot/docker/run_bot_task.py\", line 209, in '\n              '_rerender_feedstock\\n'\n              '    msg = rerender_feedstock_local(fs_dir, **kwargs)\\n'\n              '          ^^^^^^^^^^^^^^^^^^^^^^^^^^^^^^^^^^^^^^^^^^\\n'\n              '  File '\n              '\"/opt/autotick-bot/conda_forge_tick/rerender_feedstock.py\", '\n              'line 208, in rerender_feedstock_local\\n'\n              '    raise RuntimeError(f\"Failed to rerender.\\\\noutput: '\n              '{ret.stdout}\\\\n\")\\n'\n              'RuntimeError: Failed to rerender.\\n'\n              'output: Traceback (most recent call last):\\n'\n              '  File \"/opt/conda/envs/cf-scripts/bin/conda-smithy\", line 10, '\n              'in <module>\\n'\n              '    sys.exit(main())\\n'\n              '    args.subcommand_func(args)\\n'\n              '  File '\n              '\"/opt/conda/envs/cf-scripts/lib/python3.11/site-packages/conda_smithy/cli.py\", '\n              'line 589, in _call\\n'\n              '    exclusive_config_file, cf_pinning_ver = '\n              'get_cached_cfp_file_path(\\n'\n              '    current_pinning_version = get_most_recent_version(\\n'\n              '    request.raise_for_status()\\n'\n              '  File '\n              '\"/opt/conda/envs/cf-scripts/lib/python3.11/site-packages/requests/models.py\", '\n              'line 1021, in raise_for_status\\n'\n              '             ^^^^^^\\n'\n              '  File '\n              '\"/opt/conda/envs/cf-scripts/lib/python3.11/site-packages/conda_smithy/cli.py\", '\n              'line 737, in main\\n'\n              '  File '\n              '\"/opt/conda/envs/cf-scripts/lib/python3.11/site-packages/conda_smithy/cli.py\", '\n              'line 586, in __call__\\n'\n              '    self._call(args, args.temporary_directory)\\n'\n              '    configure_feedstock.main(\\n'\n              '  File '\n              '\"/opt/conda/envs/cf-scripts/lib/python3.11/site-packages/conda_smithy/configure_feedstock.py\", '\n              'line 2616, in main\\n'\n              '                                            '\n              '^^^^^^^^^^^^^^^^^^^^^^^^^\\n'\n              '  File '\n              '\"/opt/conda/envs/cf-scripts/lib/python3.11/site-packages/conda_smithy/configure_feedstock.py\", '\n              'line 2430, in get_cached_cfp_file_path\\n'\n              '                              ^^^^^^^^^^^^^^^^^^^^^^^^\\n'\n              '  File '\n              '\"/opt/conda/envs/cf-scripts/lib/python3.11/site-packages/conda_smithy/configure_feedstock.py\", '\n              'line 2300, in get_most_recent_version\\n'\n              '    raise HTTPError(http_error_msg, response=self)\\n'\n              'requests.exceptions.HTTPError: 503 Server Error: Service '\n              'Unavailable for url: '\n              'https://api.anaconda.org/package/conda-forge/conda-forge-pinning\\n'\n              '\\n'\n              '\\n'}\n"
 },
 "smithy_version": "3.23.1"
}