{
 "bad": false,
 "new_version": "0.2.7",
 "new_version_attempts": {
  "0.1.1": 1,
  "0.1.10": 1,
  "0.1.11": 1,
  "0.1.12": 1,
  "0.1.13": 1,
  "0.1.14": 1,
  "0.1.15": 1,
  "0.1.16": 1,
  "0.1.17": 1,
  "0.1.18": 1,
  "0.1.19": 1,
  "0.1.2": 1,
  "0.1.20": 1,
  "0.1.21": 1,
  "0.1.22": 1,
  "0.1.23": 1,
  "0.1.24": 1,
  "0.1.25": 1,
  "0.1.26": 1,
  "0.1.27": 1,
  "0.1.28": 1,
  "0.1.3": 1,
  "0.1.30": 1,
  "0.1.31": 1,
  "0.1.32": 1,
  "0.1.33": 1,
  "0.1.34": 1,
  "0.1.35": 1,
  "0.1.36": 1,
  "0.1.37": 1,
  "0.1.38": 1,
  "0.1.39": 1,
  "0.1.4": 1,
  "0.1.40": 1,
  "0.1.41": 1,
  "0.1.42": 1,
  "0.1.43": 1,
  "0.1.44": 1,
  "0.1.45": 1,
  "0.1.46": 1,
  "0.1.48": 1,
  "0.1.5": 1,
  "0.1.50": 1,
  "0.1.52": 1,
  "0.1.6": 1,
  "0.1.7": 1,
  "0.1.8": 1,
  "0.1.9": 1,
  "0.2.0": 1,
  "0.2.7": 1
 },
 "new_version_errors": {
  "0.2.7": "bot error (<a href=\"https://github.com/regro/cf-scripts/actions/runs/9525475998\">bot CI job</a>): main:\nError running rerender-feedstock in container - error RuntimeError raised:\n'Failed to rerender.\noutput: Traceback (most recent call last):\n  File \"/opt/conda/envs/cf-scripts/bin/conda-smithy\", line 10, in <module>\n    sys.exit(main())\n             ^^^^^^\n  File \"/opt/conda/envs/cf-scripts/lib/python3.11/site-packages/conda_smithy/cli.py\", line 737, in main\n    args.subcommand_func(args)\n  File \"/opt/conda/envs/cf-scripts/lib/python3.11/site-packages/conda_smithy/cli.py\", line 586, in __call__\n    self._call(args, args.temporary_directory)\n  File \"/opt/conda/envs/cf-scripts/lib/python3.11/site-packages/conda_smithy/cli.py\", line 589, in _call\n    configure_feedstock.main(\n  File \"/opt/conda/envs/cf-scripts/lib/python3.11/site-packages/conda_smithy/configure_feedstock.py\", line 2714, in main\n    exclusive_config_file, cf_pinning_ver = get_cached_cfp_file_path(\n                                            ^^^^^^^^^^^^^^^^^^^^^^^^^\n  File \"/opt/conda/envs/cf-scripts/lib/python3.11/site-packages/conda_smithy/configure_feedstock.py\", line 2528, in get_cached_cfp_file_path\n    current_pinning_version = get_most_recent_version(\n                              ^^^^^^^^^^^^^^^^^^^^^^^^\n  File \"/opt/conda/envs/cf-scripts/lib/python3.11/site-packages/conda_smithy/configure_feedstock.py\", line 2398, in get_most_recent_version\n    request.raise_for_status()\n  File \"/opt/conda/envs/cf-scripts/lib/python3.11/site-packages/requests/models.py\", line 1024, in raise_for_status\n    raise HTTPError(http_error_msg, response=self)\nrequests.exceptions.HTTPError: 503 Server Error: Service Unavailable for url: https://api.anaconda.org/package/conda-forge/conda-forge-pinning\n\n'"
 }
}